Traceback (most recent call last):
  File "/Users/jue/opt/anaconda3/lib/python3.8/site-packages/jupyter_cache/executors/utils.py", line 58, in single_nb_execution
    executenb(
  File "/Users/jue/opt/anaconda3/lib/python3.8/site-packages/nbclient/client.py", line 1204, in execute
    return NotebookClient(nb=nb, resources=resources, km=km, **kwargs).execute()
  File "/Users/jue/opt/anaconda3/lib/python3.8/site-packages/nbclient/util.py", line 84, in wrapped
    return just_run(coro(*args, **kwargs))
  File "/Users/jue/opt/anaconda3/lib/python3.8/site-packages/nbclient/util.py", line 62, in just_run
    return loop.run_until_complete(coro)
  File "/Users/jue/opt/anaconda3/lib/python3.8/asyncio/base_events.py", line 616, in run_until_complete
    return future.result()
  File "/Users/jue/opt/anaconda3/lib/python3.8/site-packages/nbclient/client.py", line 663, in async_execute
    await self.async_execute_cell(
  File "/Users/jue/opt/anaconda3/lib/python3.8/site-packages/nbclient/client.py", line 965, in async_execute_cell
    await self._check_raise_for_error(cell, cell_index, exec_reply)
  File "/Users/jue/opt/anaconda3/lib/python3.8/site-packages/nbclient/client.py", line 862, in _check_raise_for_error
    raise CellExecutionError.from_cell_and_msg(cell, exec_reply_content)
nbclient.exceptions.CellExecutionError: An error occurred while executing the following cell:
------------------
import matplotlib.pyplot as plt
from mpl_toolkits.mplot3d import Axes3D

%matplotlib inline

fig = plt.figure()
ax = fig.gca(projection='3d')

x =[1,2,3,4,5,6,7,8,9,10]
y =[5,6,2,3,13,4,1,2,4,8]
z =[2,3,3,3,5,7,9,11,9,10]

ax.scatter(x, y, z, c='r', marker='o')

ax.set_xlabel('X Label')
ax.set_ylabel('Y Label')
ax.set_zlabel('Z Label')

plt.show()
------------------

[0;31m---------------------------------------------------------------------------[0m
[0;31mTypeError[0m                                 Traceback (most recent call last)
[0;32m/var/folders/42/sqzr5z253691rgf7c44d8wgh0000gn/T/ipykernel_33167/2287503612.py[0m in [0;36m<module>[0;34m[0m
[1;32m      5[0m [0;34m[0m[0m
[1;32m      6[0m [0mfig[0m [0;34m=[0m [0mplt[0m[0;34m.[0m[0mfigure[0m[0;34m([0m[0;34m)[0m[0;34m[0m[0;34m[0m[0m
[0;32m----> 7[0;31m [0max[0m [0;34m=[0m [0mfig[0m[0;34m.[0m[0mgca[0m[0;34m([0m[0mprojection[0m[0;34m=[0m[0;34m'3d'[0m[0;34m)[0m[0;34m[0m[0;34m[0m[0m
[0m[1;32m      8[0m [0;34m[0m[0m
[1;32m      9[0m [0mx[0m [0;34m=[0m[0;34m[[0m[0;36m1[0m[0;34m,[0m[0;36m2[0m[0;34m,[0m[0;36m3[0m[0;34m,[0m[0;36m4[0m[0;34m,[0m[0;36m5[0m[0;34m,[0m[0;36m6[0m[0;34m,[0m[0;36m7[0m[0;34m,[0m[0;36m8[0m[0;34m,[0m[0;36m9[0m[0;34m,[0m[0;36m10[0m[0;34m][0m[0;34m[0m[0;34m[0m[0m

[0;31mTypeError[0m: gca() got an unexpected keyword argument 'projection'
TypeError: gca() got an unexpected keyword argument 'projection'

